<?xml version="1.0" ?>
<!-- =================================================================================== -->
<!-- |    This document was autogenerated by xacro from david.xacro                    | -->
<!-- |    EDITING THIS FILE BY HAND IS NOT RECOMMENDED                                 | -->
<!-- =================================================================================== -->
<robot name="david">
  <!-- Basic setup -->
  <link name="base_link"/>
  <link name="laser"/>
  <!-- <link name="depth_motor_axle" /> -->
  <!-- <link name="auger_tip" /> -->
  <!-- <link name="auger_hole"/> -->
  <!-- Locomotion component -->
  <link name="left_loco_axle"/>
  <link name="right_loco_axle"/>
  <!-- Joints -->
  <joint name="base2laser" type="fixed">
    <origin rpy="0 0 0" xyz="0 0 0"/>
    <parent link="base_link"/>
    <child link="laser"/>
    <axis xyz="0 0 0"/>
  </joint>
  <!-- Locomotion joints -->
  <joint name="loco_right" type="continuous">
    <parent link="base_link"/>
    <child link="right_loco_axle"/>
    <origin rpy="0 0 0" xyz="-0.34500000000000003 -0.27 0.07"/>
    <axis xyz="0 0 0"/>
  </joint>
  <joint name="loco_left" type="continuous">
    <parent link="base_link"/>
    <child link="left_loco_axle"/>
    <origin rpy="0 0 0" xyz="-0.34500000000000003 -0.09 0.07"/>
    <axis xyz="0 0 0"/>
  </joint>
</robot>

